Workbook

Sheet Qualiy Products at Greenweez

Sheet Sources >>

Sheet Sales
A1: =IFERROR(__xludf.DUMMYFUNCTION("IMPORTRANGE(""https://docs.google.com/spreadsheets/d/1LKNndPoZf492kzTNmSN_BQWFC4s4cYFRBWLWfm7jEr0/edit?gid=1108122911#gid=1108122911"",""Sales!A:Z"")"),"date_date") -> date_date | B1: =IFERROR(__xludf.DUMMYFUNCTION("""COMPUTED_VALUE"""),"orders_id") -> orders_id | C1: =IFERROR(__xludf.DUMMYFUNCTION("""COMPUTED_VALUE"""),"products_id") -> products_id | D1: =IFERROR(__xludf.DUMMYFUNCTION("""COMPUTED_VALUE"""),"promo_name") -> promo_name | E1: =IFERROR(__xludf.DUMMYFUNCTION("""COMPUTED_VALUE"""),"code") -> code | F1: =IFERROR(__xludf.DUMMYFUNCTION("""COMPUTED_VALUE"""),"turnover_before_promo") -> turnover_before_promo | G1: =IFERROR(__xludf.DUMMYFUNCTION("""COMPUTED_VALUE"""),"turnover") -> turnover | H1: =IFERROR(__xludf.DUMMYFUNCTION("""COMPUTED_VALUE"""),"qty") -> qty
A2: =IFERROR(__xludf.DUMMYFUNCTION("""COMPUTED_VALUE"""),44471.0) -> 44471 | B2: =IFERROR(__xludf.DUMMYFUNCTION("""COMPUTED_VALUE"""),1003283.0) -> 1003283 | C2: =IFERROR(__xludf.DUMMYFUNCTION("""COMPUTED_VALUE"""),111934.0) -> 111934 | F2: =IFERROR(__xludf.DUMMYFUNCTION("""COMPUTED_VALUE"""),20.14) -> 20.14 | G2: =IFERROR(__xludf.DUMMYFUNCTION("""COMPUTED_VALUE"""),20.14) -> 20.14 | H2: =IFERROR(__xludf.DUMMYFUNCTION("""COMPUTED_VALUE"""),1.0) -> 1
A3: =IFERROR(__xludf.DUMMYFUNCTION("""COMPUTED_VALUE"""),44471.0) -> 44471 | B3: =IFERROR(__xludf.DUMMYFUNCTION("""COMPUTED_VALUE"""),1003284.0) -> 1003284 | C3: =IFERROR(__xludf.DUMMYFUNCTION("""COMPUTED_VALUE"""),18100.0) -> 18100 | F3: =IFERROR(__xludf.DUMMYFUNCTION("""COMPUTED_VALUE"""),8.22) -> 8.22 | G3: =IFERROR(__xludf.DUMMYFUNCTION("""COMPUTED_VALUE"""),8.22) -> 8.22 | H3: =IFERROR(__xludf.DUMMYFUNCTION("""COMPUTED_VALUE"""),1.0) -> 1
A4: =IFERROR(__xludf.DUMMYFUNCTION("""COMPUTED_VALUE"""),44471.0) -> 44471 | B4: =IFERROR(__xludf.DUMMYFUNCTION("""COMPUTED_VALUE"""),1003284.0) -> 1003284 | C4: =IFERROR(__xludf.DUMMYFUNCTION("""COMPUTED_VALUE"""),109184.0) -> 109184 | F4: =IFERROR(__xludf.DUMMYFUNCTION("""COMPUTED_VALUE"""),39.37) -> 39.37 | G4: =IFERROR(__xludf.DUMMYFUNCTION("""COMPUTED_VALUE"""),39.37) -> 39.37 | H4: =IFERROR(__xludf.DUMMYFUNCTION("""COMPUTED_VALUE"""),5.0) -> 5
A5: =IFERROR(__xludf.DUMMYFUNCTION("""COMPUTED_VALUE"""),44471.0) -> 44471 | B5: =IFERROR(__xludf.DUMMYFUNCTION("""COMPUTED_VALUE"""),1003285.0) -> 1003285 | C5: =IFERROR(__xludf.DUMMYFUNCTION("""COMPUTED_VALUE"""),114912.0) -> 114912 | D5: =IFERROR(__xludf.DUMMYFUNCTION("""COMPUTED_VALUE"""),"Offre speciale") -> Offre speciale | F5: =IFERROR(__xludf.DUMMYFUNCTION("""COMPUTED_VALUE"""),7.26666666666666) -> 7.2666667 | G5: =IFERROR(__xludf.DUMMYFUNCTION("""COMPUTED_VALUE"""),6.54) -> 6.54 | H5: =IFERROR(__xludf.DUMMYFUNCTION("""COMPUTED_VALUE"""),1.0) -> 1
A6: =IFERROR(__xludf.DUMMYFUNCTION("""COMPUTED_VALUE"""),44471.0) -> 44471 | B6: =IFERROR(__xludf.DUMMYFUNCTION("""COMPUTED_VALUE"""),1003285.0) -> 1003285 | C6: =IFERROR(__xludf.DUMMYFUNCTION("""COMPUTED_VALUE"""),44718.0) -> 44718 | D6: =IFERROR(__xludf.DUMMYFUNCTION("""COMPUTED_VALUE"""),"Offre speciale") -> Offre speciale | F6: =IFERROR(__xludf.DUMMYFUNCTION("""COMPUTED_VALUE"""),1.89130434782608) -> 1.8913043 | G6: =IFERROR(__xludf.DUMMYFUNCTION("""COMPUTED_VALUE"""),1.74) -> 1.74 | H6: =IFERROR(__xludf.DUMMYFUNCTION("""COMPUTED_VALUE"""),1.0) -> 1
A7: =IFERROR(__xludf.DUMMYFUNCTION("""COMPUTED_VALUE"""),44471.0) -> 44471 | B7: =IFERROR(__xludf.DUMMYFUNCTION("""COMPUTED_VALUE"""),1003285.0) -> 1003285 | C7: =IFERROR(__xludf.DUMMYFUNCTION("""COMPUTED_VALUE"""),120255.0) -> 120255 | F7: =IFERROR(__xludf.DUMMYFUNCTION("""COMPUTED_VALUE"""),2.58) -> 2.58 | G7: =IFERROR(__xludf.DUMMYFUNCTION("""COMPUTED_VALUE"""),2.58) -> 2.58 | H7: =IFERROR(__xludf.DUMMYFUNCTION("""COMPUTED_VALUE"""),1.0) -> 1
A8: =IFERROR(__xludf.DUMMYFUNCTION("""COMPUTED_VALUE"""),44471.0) -> 44471 | B8: =IFERROR(__xludf.DUMMYFUNCTION("""COMPUTED_VALUE"""),1003285.0) -> 1003285 | C8: =IFERROR(__xludf.DUMMYFUNCTION("""COMPUTED_VALUE"""),70588.0) -> 70588 | F8: =IFERROR(__xludf.DUMMYFUNCTION("""COMPUTED_VALUE"""),0.96) -> 0.96 | G8: =IFERROR(__xludf.DUMMYFUNCTION("""COMPUTED_VALUE"""),0.96) -> 0.96 | H8: =IFERROR(__xludf.DUMMYFUNCTION("""COMPUTED_VALUE"""),1.0) -> 1
A9: =IFERROR(__xludf.DUMMYFUNCTION("""COMPUTED_VALUE"""),44471.0) -> 44471 | B9: =IFERROR(__xludf.DUMMYFUNCTION("""COMPUTED_VALUE"""),1003285.0) -> 1003285 | C9: =IFERROR(__xludf.DUMMYFUNCTION("""COMPUTED_VALUE"""),120563.0) -> 120563 | F9: =IFERROR(__xludf.DUMMYFUNCTION("""COMPUTED_VALUE"""),17.34) -> 17.34 | G9: =IFERROR(__xludf.DUMMYFUNCTION("""COMPUTED_VALUE"""),17.34) -> 17.34 | H9: =IFERROR(__xludf.DUMMYFUNCTION("""COMPUTED_VALUE"""),1.0) -> 1
A10: =IFERROR(__xludf.DUMMYFUNCTION("""COMPUTED_VALUE"""),44471.0) -> 44471 | B10: =IFERROR(__xludf.DUMMYFUNCTION("""COMPUTED_VALUE"""),1003286.0) -> 1003286 | C10: =IFERROR(__xludf.DUMMYFUNCTION("""COMPUTED_VALUE"""),5902.0) -> 5902 | E10: =IFERROR(__xludf.DUMMYFUNCTION("""COMPUTED_VALUE"""),"PREMIERE") -> PREMIERE | F10: =IFERROR(__xludf.DUMMYFUNCTION("""COMPUTED_VALUE"""),21.06) -> 21.06 | G10: =IFERROR(__xludf.DUMMYFUNCTION("""COMPUTED_VALUE"""),21.06) -> 21.06 | H10: =IFERROR(__xludf.DUMMYFUNCTION("""COMPUTED_VALUE"""),3.0) -> 3
A11: =IFERROR(__xludf.DUMMYFUNCTION("""COMPUTED_VALUE"""),44471.0) -> 44471 | B11: =IFERROR(__xludf.DUMMYFUNCTION("""COMPUTED_VALUE"""),1003286.0) -> 1003286 | C11: =IFERROR(__xludf.DUMMYFUNCTION("""COMPUTED_VALUE"""),110337.0) -> 110337 | D11: =IFERROR(__xludf.DUMMYFUNCTION("""COMPUTED_VALUE"""),"Love & Green Couches et Culottes sept 2021") -> Love & Green Couches et Culottes sept 2021 | E11: =IFERROR(__xludf.DUMMYFUNCTION("""COMPUTED_VALUE"""),"PREMIERE") -> PREMIERE | F11: =IFERROR(__xludf.DUMMYFUNCTION("""COMPUTED_VALUE"""),124.214285714285) -> 124.21429 | G11: =IFERROR(__xludf.DUMMYFUNCTION("""COMPUTED_VALUE"""),86.95) -> 86.95 | H11: =IFERROR(__xludf.DUMMYFUNCTION("""COMPUTED_VALUE"""),12.0) -> 12
A12: =IFERROR(__xludf.DUMMYFUNCTION("""COMPUTED_VALUE"""),44471.0) -> 44471 | B12: =IFERROR(__xludf.DUMMYFUNCTION("""COMPUTED_VALUE"""),1003287.0) -> 1003287 | C12: =IFERROR(__xludf.DUMMYFUNCTION("""COMPUTED_VALUE"""),79819.0) -> 79819 | F12: =IFERROR(__xludf.DUMMYFUNCTION("""COMPUTED_VALUE"""),5.77) -> 5.77 | G12: =IFERROR(__xludf.DUMMYFUNCTION("""COMPUTED_VALUE"""),5.77) -> 5.77 | H12: =IFERROR(__xludf.DUMMYFUNCTION("""COMPUTED_VALUE"""),1.0) -> 1
A13: =IFERROR(__xludf.DUMMYFUNCTION("""COMPUTED_VALUE"""),44471.0) -> 44471 | B13: =IFERROR(__xludf.DUMMYFUNCTION("""COMPUTED_VALUE"""),1003287.0) -> 1003287 | C13: =IFERROR(__xludf.DUMMYFUNCTION("""COMPUTED_VALUE"""),117464.0) -> 117464 | F13: =IFERROR(__xludf.DUMMYFUNCTION("""COMPUTED_VALUE"""),9.66) -> 9.66 | G13: =IFERROR(__xludf.DUMMYFUNCTION("""COMPUTED_VALUE"""),9.66) -> 9.66 | H13: =IFERROR(__xludf.DUMMYFUNCTION("""COMPUTED_VALUE"""),1.0) -> 1
A14: =IFERROR(__xludf.DUMMYFUNCTION("""COMPUTED_VALUE"""),44471.0) -> 44471 | B14: =IFERROR(__xludf.DUMMYFUNCTION("""COMPUTED_VALUE"""),1003287.0) -> 1003287 | C14: =IFERROR(__xludf.DUMMYFUNCTION("""COMPUTED_VALUE"""),121868.0) -> 121868 | F14: =IFERROR(__xludf.DUMMYFUNCTION("""COMPUTED_VALUE"""),6.37) -> 6.37 | G14: =IFERROR(__xludf.DUMMYFUNCTION("""COMPUTED_VALUE"""),6.37) -> 6.37 | H14: =IFERROR(__xludf.DUMMYFUNCTION("""COMPUTED_VALUE"""),1.0) -> 1
A15: =IFERROR(__xludf.DUMMYFUNCTION("""COMPUTED_VALUE"""),44471.0) -> 44471 | B15: =IFERROR(__xludf.DUMMYFUNCTION("""COMPUTED_VALUE"""),1003287.0) -> 1003287 | C15: =IFERROR(__xludf.DUMMYFUNCTION("""COMPUTED_VALUE"""),100038.0) -> 100038 | F15: =IFERROR(__xludf.DUMMYFUNCTION("""COMPUTED_VALUE"""),11.4) -> 11.4 | G15: =IFERROR(__xludf.DUMMYFUNCTION("""COMPUTED_VALUE"""),11.4) -> 11.4 | H15: =IFERROR(__xludf.DUMMYFUNCTION("""COMPUTED_VALUE"""),1.0) -> 1
A16: =IFERROR(__xludf.DUMMYFUNCTION("""COMPUTED_VALUE"""),44471.0) -> 44471 | B16: =IFERROR(__xludf.DUMMYFUNCTION("""COMPUTED_VALUE"""),1003287.0) -> 1003287 | C16: =IFERROR(__xludf.DUMMYFUNCTION("""COMPUTED_VALUE"""),119249.0) -> 119249 | F16: =IFERROR(__xludf.DUMMYFUNCTION("""COMPUTED_VALUE"""),4.74) -> 4.74 | G16: =IFERROR(__xludf.DUMMYFUNCTION("""COMPUTED_VALUE"""),4.74) -> 4.74 | H16: =IFERROR(__xludf.DUMMYFUNCTION("""COMPUTED_VALUE"""),1.0) -> 1
A17: =IFERROR(__xludf.DUMMYFUNCTION("""COMPUTED_VALUE"""),44471.0) -> 44471 | B17: =IFERROR(__xludf.DUMMYFUNCTION("""COMPUTED_VALUE"""),1003287.0) -> 1003287 | C17: =IFERROR(__xludf.DUMMYFUNCTION("""COMPUTED_VALUE"""),119257.0) -> 119257 | F17: =IFERROR(__xludf.DUMMYFUNCTION("""COMPUTED_VALUE"""),3.27) -> 3.27 | G17: =IFERROR(__xludf.DUMMYFUNCTION("""COMPUTED_VALUE"""),3.27) -> 3.27 | H17: =IFERROR(__xludf.DUMMYFUNCTION("""COMPUTED_VALUE"""),2.0) -> 2
A18: =IFERROR(__xludf.DUMMYFUNCTION("""COMPUTED_VALUE"""),44471.0) -> 44471 | B18: =IFERROR(__xludf.DUMMYFUNCTION("""COMPUTED_VALUE"""),1003287.0) -> 1003287 | C18: =IFERROR(__xludf.DUMMYFUNCTION("""COMPUTED_VALUE"""),115757.0) -> 115757 | D18: =IFERROR(__xludf.DUMMYFUNCTION("""COMPUTED_VALUE"""),"Vive le bio") -> Vive le bio | F18: =IFERROR(__xludf.DUMMYFUNCTION("""COMPUTED_VALUE"""),2.61111111111111) -> 2.6111111 | G18: =IFERROR(__xludf.DUMMYFUNCTION("""COMPUTED_VALUE"""),2.35) -> 2.35 | H18: =IFERROR(__xludf.DUMMYFUNCTION("""COMPUTED_VALUE"""),2.0) -> 2
A19: =IFERROR(__xludf.DUMMYFUNCTION("""COMPUTED_VALUE"""),44471.0) -> 44471 | B19: =IFERROR(__xludf.DUMMYFUNCTION("""COMPUTED_VALUE"""),1003287.0) -> 1003287 | C19: =IFERROR(__xludf.DUMMYFUNCTION("""COMPUTED_VALUE"""),73245.0) -> 73245 | F19: =IFERROR(__xludf.DUMMYFUNCTION("""COMPUTED_VALUE"""),2.91) -> 2.91 | G19: =IFERROR(__xludf.DUMMYFUNCTION("""COMPUTED_VALUE"""),2.91) -> 2.91 | H19: =IFERROR(__xludf.DUMMYFUNCTION("""COMPUTED_VALUE"""),2.0) -> 2
A20: =IFERROR(__xludf.DUMMYFUNCTION("""COMPUTED_VALUE"""),44471.0) -> 44471 | B20: =IFERROR(__xludf.DUMMYFUNCTION("""COMPUTED_VALUE"""),1003287.0) -> 1003287 | C20: =IFERROR(__xludf.DUMMYFUNCTION("""COMPUTED_VALUE"""),115776.0) -> 115776 | F20: =IFERROR(__xludf.DUMMYFUNCTION("""COMPUTED_VALUE"""),15.64) -> 15.64 | G20: =IFERROR(__xludf.DUMMYFUNCTION("""COMPUTED_VALUE"""),15.64) -> 15.64 | H20: =IFERROR(__xludf.DUMMYFUNCTION("""COMPUTED_VALUE"""),2.0) -> 2
A21: =IFERROR(__xludf.DUMMYFUNCTION("""COMPUTED_VALUE"""),44471.0) -> 44471 | B21: =IFERROR(__xludf.DUMMYFUNCTION("""COMPUTED_VALUE"""),1003287.0) -> 1003287 | C21: =IFERROR(__xludf.DUMMYFUNCTION("""COMPUTED_VALUE"""),115755.0) -> 115755 | F21: =IFERROR(__xludf.DUMMYFUNCTION("""COMPUTED_VALUE"""),1.92) -> 1.92 | G21: =IFERROR(__xludf.DUMMYFUNCTION("""COMPUTED_VALUE"""),1.92) -> 1.92 | H21: =IFERROR(__xludf.DUMMYFUNCTION("""COMPUTED_VALUE"""),2.0) -> 2
A22: =IFERROR(__xludf.DUMMYFUNCTION("""COMPUTED_VALUE"""),44471.0) -> 44471 | B22: =IFERROR(__xludf.DUMMYFUNCTION("""COMPUTED_VALUE"""),1003287.0) -> 1003287 | C22: =IFERROR(__xludf.DUMMYFUNCTION("""COMPUTED_VALUE"""),71420.0) -> 71420 | F22: =IFERROR(__xludf.DUMMYFUNCTION("""COMPUTED_VALUE"""),6.96) -> 6.96 | G22: =IFERROR(__xludf.DUMMYFUNCTION("""COMPUTED_VALUE"""),6.96) -> 6.96 | H22: =IFERROR(__xludf.DUMMYFUNCTION("""COMPUTED_VALUE"""),2.0) -> 2
A23: =IFERROR(__xludf.DUMMYFUNCTION("""COMPUTED_VALUE"""),44471.0) -> 44471 | B23: =IFERROR(__xludf.DUMMYFUNCTION("""COMPUTED_VALUE"""),1003287.0) -> 1003287 | C23: =IFERROR(__xludf.DUMMYFUNCTION("""COMPUTED_VALUE"""),87287.0) -> 87287 | F23: =IFERROR(__xludf.DUMMYFUNCTION("""COMPUTED_VALUE"""),4.47) -> 4.47 | G23: =IFERROR(__xludf.DUMMYFUNCTION("""COMPUTED_VALUE"""),4.47) -> 4.47 | H23: =IFERROR(__xludf.DUMMYFUNCTION("""COMPUTED_VALUE"""),2.0) -> 2
A24: =IFERROR(__xludf.DUMMYFUNCTION("""COMPUTED_VALUE"""),44471.0) -> 44471 | B24: =IFERROR(__xludf.DUMMYFUNCTION("""COMPUTED_VALUE"""),1003287.0) -> 1003287 | C24: =IFERROR(__xludf.DUMMYFUNCTION("""COMPUTED_VALUE"""),77366.0) -> 77366 | F24: =IFERROR(__xludf.DUMMYFUNCTION("""COMPUTED_VALUE"""),4.98) -> 4.98 | G24: =IFERROR(__xludf.DUMMYFUNCTION("""COMPUTED_VALUE"""),4.98) -> 4.98 | H24: =IFERROR(__xludf.DUMMYFUNCTION("""COMPUTED_VALUE"""),2.0) -> 2
A25: =IFERROR(__xludf.DUMMYFUNCTION("""COMPUTED_VALUE"""),44471.0) -> 44471 | B25: =IFERROR(__xludf.DUMMYFUNCTION("""COMPUTED_VALUE"""),1003287.0) -> 1003287 | C25: =IFERROR(__xludf.DUMMYFUNCTION("""COMPUTED_VALUE"""),87281.0) -> 87281 | F25: =IFERROR(__xludf.DUMMYFUNCTION("""COMPUTED_VALUE"""),6.24) -> 6.24 | G25: =IFERROR(__xludf.DUMMYFUNCTION("""COMPUTED_VALUE"""),6.24) -> 6.24 | H25: =IFERROR(__xludf.DUMMYFUNCTION("""COMPUTED_VALUE"""),2.0) -> 2
A26: =IFERROR(__xludf.DUMMYFUNCTION("""COMPUTED_VALUE"""),44471.0) -> 44471 | B26: =IFERROR(__xludf.DUMMYFUNCTION("""COMPUTED_VALUE"""),1003287.0) -> 1003287 | C26: =IFERROR(__xludf.DUMMYFUNCTION("""COMPUTED_VALUE"""),73260.0) -> 73260 | F26: =IFERROR(__xludf.DUMMYFUNCTION("""COMPUTED_VALUE"""),5.52) -> 5.52 | G26: =IFERROR(__xludf.DUMMYFUNCTION("""COMPUTED_VALUE"""),5.52) -> 5.52 | H26: =IFERROR(__xludf.DUMMYFUNCTION("""COMPUTED_VALUE"""),3.0) -> 3
A27: =IFERROR(__xludf.DUMMYFUNCTION("""COMPUTED_VALUE"""),44471.0) -> 44471 | B27: =IFERROR(__xludf.DUMMYFUNCTION("""COMPUTED_VALUE"""),1003287.0) -> 1003287 | C27: =IFERROR(__xludf.DUMMYFUNCTION("""COMPUTED_VALUE"""),118150.0) -> 118150 | F27: =IFERROR(__xludf.DUMMYFUNCTION("""COMPUTED_VALUE"""),5.07) -> 5.07 | G27: =IFERROR(__xludf.DUMMYFUNCTION("""COMPUTED_VALUE"""),5.07) -> 5.07 | H27: =IFERROR(__xludf.DUMMYFUNCTION("""COMPUTED_VALUE"""),3.0) -> 3
A28: =IFERROR(__xludf.DUMMYFUNCTION("""COMPUTED_VALUE"""),44471.0) -> 44471 | B28: =IFERROR(__xludf.DUMMYFUNCTION("""COMPUTED_VALUE"""),1003287.0) -> 1003287 | C28: =IFERROR(__xludf.DUMMYFUNCTION("""COMPUTED_VALUE"""),45885.0) -> 45885 | F28: =IFERROR(__xludf.DUMMYFUNCTION("""COMPUTED_VALUE"""),8.66) -> 8.66 | G28: =IFERROR(__xludf.DUMMYFUNCTION("""COMPUTED_VALUE"""),8.66) -> 8.66 | H28: =IFERROR(__xludf.DUMMYFUNCTION("""COMPUTED_VALUE"""),3.0) -> 3
A29: =IFERROR(__xludf.DUMMYFUNCTION("""COMPUTED_VALUE"""),44471.0) -> 44471 | B29: =IFERROR(__xludf.DUMMYFUNCTION("""COMPUTED_VALUE"""),1003287.0) -> 1003287 | C29: =IFERROR(__xludf.DUMMYFUNCTION("""COMPUTED_VALUE"""),73244.0) -> 73244 | F29: =IFERROR(__xludf.DUMMYFUNCTION("""COMPUTED_VALUE"""),4.37) -> 4.37 | G29: =IFERROR(__xludf.DUMMYFUNCTION("""COMPUTED_VALUE"""),4.37) -> 4.37 | H29: =IFERROR(__xludf.DUMMYFUNCTION("""COMPUTED_VALUE"""),3.0) -> 3
A30: =IFERROR(__xludf.DUMMYFUNCTION("""COMPUTED_VALUE"""),44471.0) -> 44471 | B30: =IFERROR(__xludf.DUMMYFUNCTION("""COMPUTED_VALUE"""),1003287.0) -> 1003287 | C30: =IFERROR(__xludf.DUMMYFUNCTION("""COMPUTED_VALUE"""),112246.0) -> 112246 | F30: =IFERROR(__xludf.DUMMYFUNCTION("""COMPUTED_VALUE"""),5.19) -> 5.19 | G30: =IFERROR(__xludf.DUMMYFUNCTION("""COMPUTED_VALUE"""),5.19) -> 5.19 | H30: =IFERROR(__xludf.DUMMYFUNCTION("""COMPUTED_VALUE"""),3.0) -> 3
A31: =IFERROR(__xludf.DUMMYFUNCTION("""COMPUTED_VALUE"""),44471.0) -> 44471 | B31: =IFERROR(__xludf.DUMMYFUNCTION("""COMPUTED_VALUE"""),1003288.0) -> 1003288 | C31: =IFERROR(__xludf.DUMMYFUNCTION("""COMPUTED_VALUE"""),69195.0) -> 69195 | E31: =IFERROR(__xludf.DUMMYFUNCTION("""COMPUTED_VALUE"""),"GREENRELAIS") -> GREENRELAIS | F31: =IFERROR(__xludf.DUMMYFUNCTION("""COMPUTED_VALUE"""),3.64) -> 3.64 | G31: =IFERROR(__xludf.DUMMYFUNCTION("""COMPUTED_VALUE"""),3.64) -> 3.64 | H31: =IFERROR(__xludf.DUMMYFUNCTION("""COMPUTED_VALUE"""),1.0) -> 1
A32: =IFERROR(__xludf.DUMMYFUNCTION("""COMPUTED_VALUE"""),44471.0) -> 44471 | B32: =IFERROR(__xludf.DUMMYFUNCTION("""COMPUTED_VALUE"""),1003288.0) -> 1003288 | C32: =IFERROR(__xludf.DUMMYFUNCTION("""COMPUTED_VALUE"""),120393.0) -> 120393 | E32: =IFERROR(__xludf.DUMMYFUNCTION("""COMPUTED_VALUE"""),"GREENRELAIS") -> GREENRELAIS | F32: =IFERROR(__xludf.DUMMYFUNCTION("""COMPUTED_VALUE"""),1.89) -> 1.89 | G32: =IFERROR(__xludf.DUMMYFUNCTION("""COMPUTED_VALUE"""),1.89) -> 1.89 | H32: =IFERROR(__xludf.DUMMYFUNCTION("""COMPUTED_VALUE"""),1.0) -> 1
A33: =IFERROR(__xludf.DUMMYFUNCTION("""COMPUTED_VALUE"""),44471.0) -> 44471 | B33: =IFERROR(__xludf.DUMMYFUNCTION("""COMPUTED_VALUE"""),1003288.0) -> 1003288 | C33: =IFERROR(__xludf.DUMMYFUNCTION("""COMPUTED_VALUE"""),121576.0) -> 121576 | E33: =IFERROR(__xludf.DUMMYFUNCTION("""COMPUTED_VALUE"""),"GREENRELAIS") -> GREENRELAIS | F33: =IFERROR(__xludf.DUMMYFUNCTION("""COMPUTED_VALUE"""),7.34) -> 7.34 | G33: =IFERROR(__xludf.DUMMYFUNCTION("""COMPUTED_VALUE"""),7.34) -> 7.34 | H33: =IFERROR(__xludf.DUMMYFUNCTION("""COMPUTED_VALUE"""),1.0) -> 1
A34: =IFERROR(__xludf.DUMMYFUNCTION("""COMPUTED_VALUE"""),44471.0) -> 44471 | B34: =IFERROR(__xludf.DUMMYFUNCTION("""COMPUTED_VALUE"""),1003288.0) -> 1003288 | C34: =IFERROR(__xludf.DUMMYFUNCTION("""COMPUTED_VALUE"""),112462.0) -> 112462 | D34: =IFERROR(__xludf.DUMMYFUNCTION("""COMPUTED_VALUE"""),"Offre speciale") -> Offre speciale | E34: =IFERROR(__xludf.DUMMYFUNCTION("""COMPUTED_VALUE"""),"GREENRELAIS") -> GREENRELAIS | F34: =IFERROR(__xludf.DUMMYFUNCTION("""COMPUTED_VALUE"""),1.83529411764705) -> 1.8352941 | G34: =IFERROR(__xludf.DUMMYFUNCTION("""COMPUTED_VALUE"""),1.56) -> 1.56 | H34: =IFERROR(__xludf.DUMMYFUNCTION("""COMPUTED_VALUE"""),1.0) -> 1
A35: =IFERROR(__xludf.DUMMYFUNCTION("""COMPUTED_VALUE"""),44471.0) -> 44471 | B35: =IFERROR(__xludf.DUMMYFUNCTION("""COMPUTED_VALUE"""),1003288.0) -> 1003288 | C35: =IFERROR(__xludf.DUMMYFUNCTION("""COMPUTED_VALUE"""),121708.0) -> 121708 | E35: =IFERROR(__xludf.DUMMYFUNCTION("""COMPUTED_VALUE"""),"GREENRELAIS") -> GREENRELAIS | F35: =IFERROR(__xludf.DUMMYFUNCTION("""COMPUTED_VALUE"""),13.2) -> 13.2 | G35: =IFERROR(__xludf.DUMMYFUNCTION("""COMPUTED_VALUE"""),13.2) -> 13.2 | H35: =IFERROR(__xludf.DUMMYFUNCTION("""COMPUTED_VALUE"""),1.0) -> 1
A36: =IFERROR(__xludf.DUMMYFUNCTION("""COMPUTED_VALUE"""),44471.0) -> 44471 | B36: =IFERROR(__xludf.DUMMYFUNCTION("""COMPUTED_VALUE"""),1003288.0) -> 1003288 | C36: =IFERROR(__xludf.DUMMYFUNCTION("""COMPUTED_VALUE"""),77475.0) -> 77475 | D36: =IFERROR(__xludf.DUMMYFUNCTION("""COMPUTED_VALUE"""),"Vive le bio") -> Vive le bio | E36: =IFERROR(__xludf.DUMMYFUNCTION("""COMPUTED_VALUE"""),"GREENRELAIS") -> GREENRELAIS | F36: =IFERROR(__xludf.DUMMYFUNCTION("""COMPUTED_VALUE"""),1.25555555555555) -> 1.2555556 | G36: =IFERROR(__xludf.DUMMYFUNCTION("""COMPUTED_VALUE"""),1.13) -> 1.13 | H36: =IFERROR(__xludf.DUMMYFUNCTION("""COMPUTED_VALUE"""),1.0) -> 1
A37: =IFERROR(__xludf.DUMMYFUNCTION("""COMPUTED_VALUE"""),44471.0) -> 44471 | B37: =IFERROR(__xludf.DUMMYFUNCTION("""COMPUTED_VALUE"""),1003288.0) -> 1003288 | C37: =IFERROR(__xludf.DUMMYFUNCTION("""COMPUTED_VALUE"""),77326.0) -> 77326 | E37: =IFERROR(__xludf.DUMMYFUNCTION("""COMPUTED_VALUE"""),"GREENRELAIS") -> GREENRELAIS | F37: =IFERROR(__xludf.DUMMYFUNCTION("""COMPUTED_VALUE"""),2.85) -> 2.85 | G37: =IFERROR(__xludf.DUMMYFUNCTION("""COMPUTED_VALUE"""),2.85) -> 2.85 | H37: =IFERROR(__xludf.DUMMYFUNCTION("""COMPUTED_VALUE"""),1.0) -> 1
A38: =IFERROR(__xludf.DUMMYFUNCTION("""COMPUTED_VALUE"""),44471.0) -> 44471 | B38: =IFERROR(__xludf.DUMMYFUNCTION("""COMPUTED_VALUE"""),1003288.0) -> 1003288 | C38: =IFERROR(__xludf.DUMMYFUNCTION("""COMPUTED_VALUE"""),111946.0) -> 111946 | E38: =IFERROR(__xludf.DUMMYFUNCTION("""COMPUTED_VALUE"""),"GREENRELAIS") -> GREENRELAIS | F38: =IFERROR(__xludf.DUMMYFUNCTION("""COMPUTED_VALUE"""),3.48) -> 3.48 | G38: =IFERROR(__xludf.DUMMYFUNCTION("""COMPUTED_VALUE"""),3.48) -> 3.48 | H38: =IFERROR(__xludf.DUMMYFUNCTION("""COMPUTED_VALUE"""),1.0) -> 1
A39: =IFERROR(__xludf.DUMMYFUNCTION("""COMPUTED_VALUE"""),44471.0) -> 44471 | B39: =IFERROR(__xludf.DUMMYFUNCTION("""COMPUTED_VALUE"""),1003288.0) -> 1003288 | C39: =IFERROR(__xludf.DUMMYFUNCTION("""COMPUTED_VALUE"""),87160.0) -> 87160 | E39: =IFERROR(__xludf.DUMMYFUNCTION("""COMPUTED_VALUE"""),"GREENRELAIS") -> GREENRELAIS | F39: =IFERROR(__xludf.DUMMYFUNCTION("""COMPUTED_VALUE"""),4.69) -> 4.69 | G39: =IFERROR(__xludf.DUMMYFUNCTION("""COMPUTED_VALUE"""),4.69) -> 4.69 | H39: =IFERROR(__xludf.DUMMYFUNCTION("""COMPUTED_VALUE"""),2.0) -> 2
A40: =IFERROR(__xludf.DUMMYFUNCTION("""COMPUTED_VALUE"""),44471.0) -> 44471 | B40: =IFERROR(__xludf.DUMMYFUNCTION("""COMPUTED_VALUE"""),1003288.0) -> 1003288 | C40: =IFERROR(__xludf.DUMMYFUNCTION("""COMPUTED_VALUE"""),129479.0) -> 129479 | E40: =IFERROR(__xludf.DUMMYFUNCTION("""COMPUTED_VALUE"""),"GREENRELAIS") -> GREENRELAIS | F40: =IFERROR(__xludf.DUMMYFUNCTION("""COMPUTED_VALUE"""),7.98) -> 7.98 | G40: =IFERROR(__xludf.DUMMYFUNCTION("""COMPUTED_VALUE"""),7.98) -> 7.98 | H40: =IFERROR(__xludf.DUMMYFUNCTION("""COMPUTED_VALUE"""),3.0) -> 3
...

Sheet Refund_reason
A1: =IFERROR(__xludf.DUMMYFUNCTION("IMPORTRANGE(""https://docs.google.com/spreadsheets/d/1KBPZL6V6t1wQfIul5MfDBzVW_E1qX9_5Nn6Omd0L7JY/edit?gid=164626335#gid=164626335"",""refund_reason!A:Z"")"),"year") -> year | B1: =IFERROR(__xludf.DUMMYFUNCTION("""COMPUTED_VALUE"""),"month") -> month | C1: =IFERROR(__xludf.DUMMYFUNCTION("""COMPUTED_VALUE"""),"day") -> day | D1: =IFERROR(__xludf.DUMMYFUNCTION("""COMPUTED_VALUE"""),"orders_id") -> orders_id | E1: =IFERROR(__xludf.DUMMYFUNCTION("""COMPUTED_VALUE"""),"ref_turnover") -> ref_turnover | F1: =IFERROR(__xludf.DUMMYFUNCTION("""COMPUTED_VALUE"""),"ref_ship") -> ref_ship | G1: =IFERROR(__xludf.DUMMYFUNCTION("""COMPUTED_VALUE"""),"ref_coupon") -> ref_coupon | H1: =IFERROR(__xludf.DUMMYFUNCTION("""COMPUTED_VALUE"""),"ref_reason") -> ref_reason
A2: =IFERROR(__xludf.DUMMYFUNCTION("""COMPUTED_VALUE"""),2021.0) -> 2021 | B2: =IFERROR(__xludf.DUMMYFUNCTION("""COMPUTED_VALUE"""),10.0) -> 10 | C2: =IFERROR(__xludf.DUMMYFUNCTION("""COMPUTED_VALUE"""),1.0) -> 1 | D2: =IFERROR(__xludf.DUMMYFUNCTION("""COMPUTED_VALUE"""),1003644.0) -> 1003644 | E2: =IFERROR(__xludf.DUMMYFUNCTION("""COMPUTED_VALUE"""),6.0) -> 6 | F2: =IFERROR(__xludf.DUMMYFUNCTION("""COMPUTED_VALUE"""),0.0) -> 0 | G2: =IFERROR(__xludf.DUMMYFUNCTION("""COMPUTED_VALUE"""),0.0) -> 0 | H2: =IFERROR(__xludf.DUMMYFUNCTION("""COMPUTED_VALUE"""),"Damage") -> Damage
A3: =IFERROR(__xludf.DUMMYFUNCTION("""COMPUTED_VALUE"""),2021.0) -> 2021 | B3: =IFERROR(__xludf.DUMMYFUNCTION("""COMPUTED_VALUE"""),10.0) -> 10 | C3: =IFERROR(__xludf.DUMMYFUNCTION("""COMPUTED_VALUE"""),1.0) -> 1 | D3: =IFERROR(__xludf.DUMMYFUNCTION("""COMPUTED_VALUE"""),1003989.0) -> 1003989 | E3: =IFERROR(__xludf.DUMMYFUNCTION("""COMPUTED_VALUE"""),3.0) -> 3 | F3: =IFERROR(__xludf.DUMMYFUNCTION("""COMPUTED_VALUE"""),0.0) -> 0 | G3: =IFERROR(__xludf.DUMMYFUNCTION("""COMPUTED_VALUE"""),0.0) -> 0 | H3: =IFERROR(__xludf.DUMMYFUNCTION("""COMPUTED_VALUE"""),"Wrong product") -> Wrong product
A4: =IFERROR(__xludf.DUMMYFUNCTION("""COMPUTED_VALUE"""),2021.0) -> 2021 | B4: =IFERROR(__xludf.DUMMYFUNCTION("""COMPUTED_VALUE"""),10.0) -> 10 | C4: =IFERROR(__xludf.DUMMYFUNCTION("""COMPUTED_VALUE"""),1.0) -> 1 | D4: =IFERROR(__xludf.DUMMYFUNCTION("""COMPUTED_VALUE"""),1003585.0) -> 1003585 | E4: =IFERROR(__xludf.DUMMYFUNCTION("""COMPUTED_VALUE"""),1.0) -> 1 | F4: =IFERROR(__xludf.DUMMYFUNCTION("""COMPUTED_VALUE"""),0.0) -> 0 | G4: =IFERROR(__xludf.DUMMYFUNCTION("""COMPUTED_VALUE"""),0.0) -> 0 | H4: =IFERROR(__xludf.DUMMYFUNCTION("""COMPUTED_VALUE"""),"Wrong product") -> Wrong product
A5: =IFERROR(__xludf.DUMMYFUNCTION("""COMPUTED_VALUE"""),2021.0) -> 2021 | B5: =IFERROR(__xludf.DUMMYFUNCTION("""COMPUTED_VALUE"""),10.0) -> 10 | C5: =IFERROR(__xludf.DUMMYFUNCTION("""COMPUTED_VALUE"""),1.0) -> 1 | D5: =IFERROR(__xludf.DUMMYFUNCTION("""COMPUTED_VALUE"""),1003362.0) -> 1003362 | E5: =IFERROR(__xludf.DUMMYFUNCTION("""COMPUTED_VALUE"""),3.0) -> 3 | F5: =IFERROR(__xludf.DUMMYFUNCTION("""COMPUTED_VALUE"""),0.0) -> 0 | G5: =IFERROR(__xludf.DUMMYFUNCTION("""COMPUTED_VALUE"""),0.0) -> 0 | H5: =IFERROR(__xludf.DUMMYFUNCTION("""COMPUTED_VALUE"""),"Wrong product") -> Wrong product
A6: =IFERROR(__xludf.DUMMYFUNCTION("""COMPUTED_VALUE"""),2021.0) -> 2021 | B6: =IFERROR(__xludf.DUMMYFUNCTION("""COMPUTED_VALUE"""),10.0) -> 10 | C6: =IFERROR(__xludf.DUMMYFUNCTION("""COMPUTED_VALUE"""),1.0) -> 1 | D6: =IFERROR(__xludf.DUMMYFUNCTION("""COMPUTED_VALUE"""),1003322.0) -> 1003322 | E6: =IFERROR(__xludf.DUMMYFUNCTION("""COMPUTED_VALUE"""),1.0) -> 1 | F6: =IFERROR(__xludf.DUMMYFUNCTION("""COMPUTED_VALUE"""),0.0) -> 0 | G6: =IFERROR(__xludf.DUMMYFUNCTION("""COMPUTED_VALUE"""),10.0) -> 10 | H6: =IFERROR(__xludf.DUMMYFUNCTION("""COMPUTED_VALUE"""),"Return") -> Return
A7: =IFERROR(__xludf.DUMMYFUNCTION("""COMPUTED_VALUE"""),2021.0) -> 2021 | B7: =IFERROR(__xludf.DUMMYFUNCTION("""COMPUTED_VALUE"""),10.0) -> 10 | C7: =IFERROR(__xludf.DUMMYFUNCTION("""COMPUTED_VALUE"""),1.0) -> 1 | D7: =IFERROR(__xludf.DUMMYFUNCTION("""COMPUTED_VALUE"""),1003992.0) -> 1003992 | E7: =IFERROR(__xludf.DUMMYFUNCTION("""COMPUTED_VALUE"""),13.0) -> 13 | F7: =IFERROR(__xludf.DUMMYFUNCTION("""COMPUTED_VALUE"""),0.0) -> 0 | G7: =IFERROR(__xludf.DUMMYFUNCTION("""COMPUTED_VALUE"""),0.0) -> 0 | H7: =IFERROR(__xludf.DUMMYFUNCTION("""COMPUTED_VALUE"""),"Return") -> Return
A8: =IFERROR(__xludf.DUMMYFUNCTION("""COMPUTED_VALUE"""),2021.0) -> 2021 | B8: =IFERROR(__xludf.DUMMYFUNCTION("""COMPUTED_VALUE"""),10.0) -> 10 | C8: =IFERROR(__xludf.DUMMYFUNCTION("""COMPUTED_VALUE"""),1.0) -> 1 | D8: =IFERROR(__xludf.DUMMYFUNCTION("""COMPUTED_VALUE"""),1003540.0) -> 1003540 | E8: =IFERROR(__xludf.DUMMYFUNCTION("""COMPUTED_VALUE"""),2.0) -> 2 | F8: =IFERROR(__xludf.DUMMYFUNCTION("""COMPUTED_VALUE"""),0.0) -> 0 | G8: =IFERROR(__xludf.DUMMYFUNCTION("""COMPUTED_VALUE"""),0.0) -> 0 | H8: =IFERROR(__xludf.DUMMYFUNCTION("""COMPUTED_VALUE"""),"Return") -> Return
A9: =IFERROR(__xludf.DUMMYFUNCTION("""COMPUTED_VALUE"""),2021.0) -> 2021 | B9: =IFERROR(__xludf.DUMMYFUNCTION("""COMPUTED_VALUE"""),10.0) -> 10 | C9: =IFERROR(__xludf.DUMMYFUNCTION("""COMPUTED_VALUE"""),1.0) -> 1 | D9: =IFERROR(__xludf.DUMMYFUNCTION("""COMPUTED_VALUE"""),1003712.0) -> 1003712 | E9: =IFERROR(__xludf.DUMMYFUNCTION("""COMPUTED_VALUE"""),0.7595799120798356) -> 0.75957991 | F9: =IFERROR(__xludf.DUMMYFUNCTION("""COMPUTED_VALUE"""),0.0) -> 0 | G9: =IFERROR(__xludf.DUMMYFUNCTION("""COMPUTED_VALUE"""),10.0) -> 10 | H9: =IFERROR(__xludf.DUMMYFUNCTION("""COMPUTED_VALUE"""),"Return") -> Return
A10: =IFERROR(__xludf.DUMMYFUNCTION("""COMPUTED_VALUE"""),2021.0) -> 2021 | B10: =IFERROR(__xludf.DUMMYFUNCTION("""COMPUTED_VALUE"""),10.0) -> 10 | C10: =IFERROR(__xludf.DUMMYFUNCTION("""COMPUTED_VALUE"""),1.0) -> 1 | D10: =IFERROR(__xludf.DUMMYFUNCTION("""COMPUTED_VALUE"""),1003802.0) -> 1003802 | E10: =IFERROR(__xludf.DUMMYFUNCTION("""COMPUTED_VALUE"""),2.0) -> 2 | F10: =IFERROR(__xludf.DUMMYFUNCTION("""COMPUTED_VALUE"""),0.0) -> 0 | G10: =IFERROR(__xludf.DUMMYFUNCTION("""COMPUTED_VALUE"""),0.0) -> 0 | H10: =IFERROR(__xludf.DUMMYFUNCTION("""COMPUTED_VALUE"""),"Damage") -> Damage
A11: =IFERROR(__xludf.DUMMYFUNCTION("""COMPUTED_VALUE"""),2021.0) -> 2021 | B11: =IFERROR(__xludf.DUMMYFUNCTION("""COMPUTED_VALUE"""),10.0) -> 10 | C11: =IFERROR(__xludf.DUMMYFUNCTION("""COMPUTED_VALUE"""),1.0) -> 1 | D11: =IFERROR(__xludf.DUMMYFUNCTION("""COMPUTED_VALUE"""),1003568.0) -> 1003568 | E11: =IFERROR(__xludf.DUMMYFUNCTION("""COMPUTED_VALUE"""),3.0) -> 3 | F11: =IFERROR(__xludf.DUMMYFUNCTION("""COMPUTED_VALUE"""),5.75) -> 5.75 | G11: =IFERROR(__xludf.DUMMYFUNCTION("""COMPUTED_VALUE"""),0.0) -> 0 | H11: =IFERROR(__xludf.DUMMYFUNCTION("""COMPUTED_VALUE"""),"Return") -> Return
A12: =IFERROR(__xludf.DUMMYFUNCTION("""COMPUTED_VALUE"""),2021.0) -> 2021 | B12: =IFERROR(__xludf.DUMMYFUNCTION("""COMPUTED_VALUE"""),10.0) -> 10 | C12: =IFERROR(__xludf.DUMMYFUNCTION("""COMPUTED_VALUE"""),1.0) -> 1 | D12: =IFERROR(__xludf.DUMMYFUNCTION("""COMPUTED_VALUE"""),1003822.0) -> 1003822 | E12: =IFERROR(__xludf.DUMMYFUNCTION("""COMPUTED_VALUE"""),2.0) -> 2 | F12: =IFERROR(__xludf.DUMMYFUNCTION("""COMPUTED_VALUE"""),0.0) -> 0 | G12: =IFERROR(__xludf.DUMMYFUNCTION("""COMPUTED_VALUE"""),0.0) -> 0 | H12: =IFERROR(__xludf.DUMMYFUNCTION("""COMPUTED_VALUE"""),"Return") -> Return
A13: =IFERROR(__xludf.DUMMYFUNCTION("""COMPUTED_VALUE"""),2021.0) -> 2021 | B13: =IFERROR(__xludf.DUMMYFUNCTION("""COMPUTED_VALUE"""),10.0) -> 10 | C13: =IFERROR(__xludf.DUMMYFUNCTION("""COMPUTED_VALUE"""),1.0) -> 1 | D13: =IFERROR(__xludf.DUMMYFUNCTION("""COMPUTED_VALUE"""),1003395.0) -> 1003395 | E13: =IFERROR(__xludf.DUMMYFUNCTION("""COMPUTED_VALUE"""),1.0) -> 1 | F13: =IFERROR(__xludf.DUMMYFUNCTION("""COMPUTED_VALUE"""),0.0) -> 0 | G13: =IFERROR(__xludf.DUMMYFUNCTION("""COMPUTED_VALUE"""),10.0) -> 10 | H13: =IFERROR(__xludf.DUMMYFUNCTION("""COMPUTED_VALUE"""),"Return") -> Return
A14: =IFERROR(__xludf.DUMMYFUNCTION("""COMPUTED_VALUE"""),2021.0) -> 2021 | B14: =IFERROR(__xludf.DUMMYFUNCTION("""COMPUTED_VALUE"""),10.0) -> 10 | C14: =IFERROR(__xludf.DUMMYFUNCTION("""COMPUTED_VALUE"""),1.0) -> 1 | D14: =IFERROR(__xludf.DUMMYFUNCTION("""COMPUTED_VALUE"""),1003641.0) -> 1003641 | E14: =IFERROR(__xludf.DUMMYFUNCTION("""COMPUTED_VALUE"""),9.0) -> 9 | F14: =IFERROR(__xludf.DUMMYFUNCTION("""COMPUTED_VALUE"""),0.0) -> 0 | G14: =IFERROR(__xludf.DUMMYFUNCTION("""COMPUTED_VALUE"""),0.0) -> 0 | H14: =IFERROR(__xludf.DUMMYFUNCTION("""COMPUTED_VALUE"""),"Return") -> Return
A15: =IFERROR(__xludf.DUMMYFUNCTION("""COMPUTED_VALUE"""),2021.0) -> 2021 | B15: =IFERROR(__xludf.DUMMYFUNCTION("""COMPUTED_VALUE"""),10.0) -> 10 | C15: =IFERROR(__xludf.DUMMYFUNCTION("""COMPUTED_VALUE"""),1.0) -> 1 | D15: =IFERROR(__xludf.DUMMYFUNCTION("""COMPUTED_VALUE"""),1003698.0) -> 1003698 | E15: =IFERROR(__xludf.DUMMYFUNCTION("""COMPUTED_VALUE"""),1.0) -> 1 | F15: =IFERROR(__xludf.DUMMYFUNCTION("""COMPUTED_VALUE"""),6.64) -> 6.64 | G15: =IFERROR(__xludf.DUMMYFUNCTION("""COMPUTED_VALUE"""),0.0) -> 0 | H15: =IFERROR(__xludf.DUMMYFUNCTION("""COMPUTED_VALUE"""),"Return") -> Return
A16: =IFERROR(__xludf.DUMMYFUNCTION("""COMPUTED_VALUE"""),2021.0) -> 2021 | B16: =IFERROR(__xludf.DUMMYFUNCTION("""COMPUTED_VALUE"""),10.0) -> 10 | C16: =IFERROR(__xludf.DUMMYFUNCTION("""COMPUTED_VALUE"""),1.0) -> 1 | D16: =IFERROR(__xludf.DUMMYFUNCTION("""COMPUTED_VALUE"""),1003880.0) -> 1003880 | E16: =IFERROR(__xludf.DUMMYFUNCTION("""COMPUTED_VALUE"""),2.0) -> 2 | F16: =IFERROR(__xludf.DUMMYFUNCTION("""COMPUTED_VALUE"""),4.63) -> 4.63 | G16: =IFERROR(__xludf.DUMMYFUNCTION("""COMPUTED_VALUE"""),0.0) -> 0 | H16: =IFERROR(__xludf.DUMMYFUNCTION("""COMPUTED_VALUE"""),"Return") -> Return
A17: =IFERROR(__xludf.DUMMYFUNCTION("""COMPUTED_VALUE"""),2021.0) -> 2021 | B17: =IFERROR(__xludf.DUMMYFUNCTION("""COMPUTED_VALUE"""),10.0) -> 10 | C17: =IFERROR(__xludf.DUMMYFUNCTION("""COMPUTED_VALUE"""),1.0) -> 1 | D17: =IFERROR(__xludf.DUMMYFUNCTION("""COMPUTED_VALUE"""),1003851.0) -> 1003851 | E17: =IFERROR(__xludf.DUMMYFUNCTION("""COMPUTED_VALUE"""),2.0) -> 2 | F17: =IFERROR(__xludf.DUMMYFUNCTION("""COMPUTED_VALUE"""),0.0) -> 0 | G17: =IFERROR(__xludf.DUMMYFUNCTION("""COMPUTED_VALUE"""),0.0) -> 0 | H17: =IFERROR(__xludf.DUMMYFUNCTION("""COMPUTED_VALUE"""),"Damage") -> Damage
A18: =IFERROR(__xludf.DUMMYFUNCTION("""COMPUTED_VALUE"""),2021.0) -> 2021 | B18: =IFERROR(__xludf.DUMMYFUNCTION("""COMPUTED_VALUE"""),10.0) -> 10 | C18: =IFERROR(__xludf.DUMMYFUNCTION("""COMPUTED_VALUE"""),1.0) -> 1 | D18: =IFERROR(__xludf.DUMMYFUNCTION("""COMPUTED_VALUE"""),1003501.0) -> 1003501 | E18: =IFERROR(__xludf.DUMMYFUNCTION("""COMPUTED_VALUE"""),1.0) -> 1 | F18: =IFERROR(__xludf.DUMMYFUNCTION("""COMPUTED_VALUE"""),0.0) -> 0 | G18: =IFERROR(__xludf.DUMMYFUNCTION("""COMPUTED_VALUE"""),5.0) -> 5 | H18: =IFERROR(__xludf.DUMMYFUNCTION("""COMPUTED_VALUE"""),"Return") -> Return
A19: =IFERROR(__xludf.DUMMYFUNCTION("""COMPUTED_VALUE"""),2021.0) -> 2021 | B19: =IFERROR(__xludf.DUMMYFUNCTION("""COMPUTED_VALUE"""),10.0) -> 10 | C19: =IFERROR(__xludf.DUMMYFUNCTION("""COMPUTED_VALUE"""),1.0) -> 1 | D19: =IFERROR(__xludf.DUMMYFUNCTION("""COMPUTED_VALUE"""),1004010.0) -> 1004010 | E19: =IFERROR(__xludf.DUMMYFUNCTION("""COMPUTED_VALUE"""),1.0) -> 1 | F19: =IFERROR(__xludf.DUMMYFUNCTION("""COMPUTED_VALUE"""),0.0) -> 0 | G19: =IFERROR(__xludf.DUMMYFUNCTION("""COMPUTED_VALUE"""),0.0) -> 0 | H19: =IFERROR(__xludf.DUMMYFUNCTION("""COMPUTED_VALUE"""),"Wrong product") -> Wrong product
A20: =IFERROR(__xludf.DUMMYFUNCTION("""COMPUTED_VALUE"""),2021.0) -> 2021 | B20: =IFERROR(__xludf.DUMMYFUNCTION("""COMPUTED_VALUE"""),10.0) -> 10 | C20: =IFERROR(__xludf.DUMMYFUNCTION("""COMPUTED_VALUE"""),1.0) -> 1 | D20: =IFERROR(__xludf.DUMMYFUNCTION("""COMPUTED_VALUE"""),1003808.0) -> 1003808 | E20: =IFERROR(__xludf.DUMMYFUNCTION("""COMPUTED_VALUE"""),0.43335126759828724) -> 0.43335127 | F20: =IFERROR(__xludf.DUMMYFUNCTION("""COMPUTED_VALUE"""),0.0) -> 0 | G20: =IFERROR(__xludf.DUMMYFUNCTION("""COMPUTED_VALUE"""),0.0) -> 0 | H20: =IFERROR(__xludf.DUMMYFUNCTION("""COMPUTED_VALUE"""),"Wrong product") -> Wrong product
A21: =IFERROR(__xludf.DUMMYFUNCTION("""COMPUTED_VALUE"""),2021.0) -> 2021 | B21: =IFERROR(__xludf.DUMMYFUNCTION("""COMPUTED_VALUE"""),10.0) -> 10 | C21: =IFERROR(__xludf.DUMMYFUNCTION("""COMPUTED_VALUE"""),1.0) -> 1 | D21: =IFERROR(__xludf.DUMMYFUNCTION("""COMPUTED_VALUE"""),1003454.0) -> 1003454 | E21: =IFERROR(__xludf.DUMMYFUNCTION("""COMPUTED_VALUE"""),4.0) -> 4 | F21: =IFERROR(__xludf.DUMMYFUNCTION("""COMPUTED_VALUE"""),0.0) -> 0 | G21: =IFERROR(__xludf.DUMMYFUNCTION("""COMPUTED_VALUE"""),0.0) -> 0 | H21: =IFERROR(__xludf.DUMMYFUNCTION("""COMPUTED_VALUE"""),"Wrong product") -> Wrong product
A22: =IFERROR(__xludf.DUMMYFUNCTION("""COMPUTED_VALUE"""),2021.0) -> 2021 | B22: =IFERROR(__xludf.DUMMYFUNCTION("""COMPUTED_VALUE"""),10.0) -> 10 | C22: =IFERROR(__xludf.DUMMYFUNCTION("""COMPUTED_VALUE"""),1.0) -> 1 | D22: =IFERROR(__xludf.DUMMYFUNCTION("""COMPUTED_VALUE"""),1003446.0) -> 1003446 | E22: =IFERROR(__xludf.DUMMYFUNCTION("""COMPUTED_VALUE"""),3.0) -> 3 | F22: =IFERROR(__xludf.DUMMYFUNCTION("""COMPUTED_VALUE"""),0.0) -> 0 | G22: =IFERROR(__xludf.DUMMYFUNCTION("""COMPUTED_VALUE"""),0.0) -> 0 | H22: =IFERROR(__xludf.DUMMYFUNCTION("""COMPUTED_VALUE"""),"Wrong product") -> Wrong product
A23: =IFERROR(__xludf.DUMMYFUNCTION("""COMPUTED_VALUE"""),2021.0) -> 2021 | B23: =IFERROR(__xludf.DUMMYFUNCTION("""COMPUTED_VALUE"""),10.0) -> 10 | C23: =IFERROR(__xludf.DUMMYFUNCTION("""COMPUTED_VALUE"""),1.0) -> 1 | D23: =IFERROR(__xludf.DUMMYFUNCTION("""COMPUTED_VALUE"""),1003723.0) -> 1003723 | E23: =IFERROR(__xludf.DUMMYFUNCTION("""COMPUTED_VALUE"""),1.0) -> 1 | F23: =IFERROR(__xludf.DUMMYFUNCTION("""COMPUTED_VALUE"""),0.0) -> 0 | G23: =IFERROR(__xludf.DUMMYFUNCTION("""COMPUTED_VALUE"""),0.0) -> 0 | H23: =IFERROR(__xludf.DUMMYFUNCTION("""COMPUTED_VALUE"""),"Damage") -> Damage
A24: =IFERROR(__xludf.DUMMYFUNCTION("""COMPUTED_VALUE"""),2021.0) -> 2021 | B24: =IFERROR(__xludf.DUMMYFUNCTION("""COMPUTED_VALUE"""),10.0) -> 10 | C24: =IFERROR(__xludf.DUMMYFUNCTION("""COMPUTED_VALUE"""),1.0) -> 1 | D24: =IFERROR(__xludf.DUMMYFUNCTION("""COMPUTED_VALUE"""),1003634.0) -> 1003634 | E24: =IFERROR(__xludf.DUMMYFUNCTION("""COMPUTED_VALUE"""),3.0) -> 3 | F24: =IFERROR(__xludf.DUMMYFUNCTION("""COMPUTED_VALUE"""),0.0) -> 0 | G24: =IFERROR(__xludf.DUMMYFUNCTION("""COMPUTED_VALUE"""),0.0) -> 0 | H24: =IFERROR(__xludf.DUMMYFUNCTION("""COMPUTED_VALUE"""),"Damage") -> Damage
A25: =IFERROR(__xludf.DUMMYFUNCTION("""COMPUTED_VALUE"""),2021.0) -> 2021 | B25: =IFERROR(__xludf.DUMMYFUNCTION("""COMPUTED_VALUE"""),10.0) -> 10 | C25: =IFERROR(__xludf.DUMMYFUNCTION("""COMPUTED_VALUE"""),1.0) -> 1 | D25: =IFERROR(__xludf.DUMMYFUNCTION("""COMPUTED_VALUE"""),1003584.0) -> 1003584 | E25: =IFERROR(__xludf.DUMMYFUNCTION("""COMPUTED_VALUE"""),1.0) -> 1 | F25: =IFERROR(__xludf.DUMMYFUNCTION("""COMPUTED_VALUE"""),0.0) -> 0 | G25: =IFERROR(__xludf.DUMMYFUNCTION("""COMPUTED_VALUE"""),0.0) -> 0 | H25: =IFERROR(__xludf.DUMMYFUNCTION("""COMPUTED_VALUE"""),"Wrong product") -> Wrong product
A26: =IFERROR(__xludf.DUMMYFUNCTION("""COMPUTED_VALUE"""),2021.0) -> 2021 | B26: =IFERROR(__xludf.DUMMYFUNCTION("""COMPUTED_VALUE"""),10.0) -> 10 | C26: =IFERROR(__xludf.DUMMYFUNCTION("""COMPUTED_VALUE"""),1.0) -> 1 | D26: =IFERROR(__xludf.DUMMYFUNCTION("""COMPUTED_VALUE"""),1003298.0) -> 1003298 | E26: =IFERROR(__xludf.DUMMYFUNCTION("""COMPUTED_VALUE"""),18.0) -> 18 | F26: =IFERROR(__xludf.DUMMYFUNCTION("""COMPUTED_VALUE"""),0.0) -> 0 | G26: =IFERROR(__xludf.DUMMYFUNCTION("""COMPUTED_VALUE"""),8.0) -> 8 | H26: =IFERROR(__xludf.DUMMYFUNCTION("""COMPUTED_VALUE"""),"Return") -> Return
A27: =IFERROR(__xludf.DUMMYFUNCTION("""COMPUTED_VALUE"""),2021.0) -> 2021 | B27: =IFERROR(__xludf.DUMMYFUNCTION("""COMPUTED_VALUE"""),10.0) -> 10 | C27: =IFERROR(__xludf.DUMMYFUNCTION("""COMPUTED_VALUE"""),1.0) -> 1 | D27: =IFERROR(__xludf.DUMMYFUNCTION("""COMPUTED_VALUE"""),1003500.0) -> 1003500 | E27: =IFERROR(__xludf.DUMMYFUNCTION("""COMPUTED_VALUE"""),3.0) -> 3 | F27: =IFERROR(__xludf.DUMMYFUNCTION("""COMPUTED_VALUE"""),0.0) -> 0 | G27: =IFERROR(__xludf.DUMMYFUNCTION("""COMPUTED_VALUE"""),0.0) -> 0 | H27: =IFERROR(__xludf.DUMMYFUNCTION("""COMPUTED_VALUE"""),"Damage") -> Damage
A28: =IFERROR(__xludf.DUMMYFUNCTION("""COMPUTED_VALUE"""),2021.0) -> 2021 | B28: =IFERROR(__xludf.DUMMYFUNCTION("""COMPUTED_VALUE"""),10.0) -> 10 | C28: =IFERROR(__xludf.DUMMYFUNCTION("""COMPUTED_VALUE"""),1.0) -> 1 | D28: =IFERROR(__xludf.DUMMYFUNCTION("""COMPUTED_VALUE"""),1003730.0) -> 1003730 | E28: =IFERROR(__xludf.DUMMYFUNCTION("""COMPUTED_VALUE"""),3.0) -> 3 | F28: =IFERROR(__xludf.DUMMYFUNCTION("""COMPUTED_VALUE"""),0.0) -> 0 | G28: =IFERROR(__xludf.DUMMYFUNCTION("""COMPUTED_VALUE"""),0.0) -> 0 | H28: =IFERROR(__xludf.DUMMYFUNCTION("""COMPUTED_VALUE"""),"Damage") -> Damage
A29: =IFERROR(__xludf.DUMMYFUNCTION("""COMPUTED_VALUE"""),2021.0) -> 2021 | B29: =IFERROR(__xludf.DUMMYFUNCTION("""COMPUTED_VALUE"""),10.0) -> 10 | C29: =IFERROR(__xludf.DUMMYFUNCTION("""COMPUTED_VALUE"""),1.0) -> 1 | D29: =IFERROR(__xludf.DUMMYFUNCTION("""COMPUTED_VALUE"""),1003312.0) -> 1003312 | E29: =IFERROR(__xludf.DUMMYFUNCTION("""COMPUTED_VALUE"""),6.0) -> 6 | F29: =IFERROR(__xludf.DUMMYFUNCTION("""COMPUTED_VALUE"""),0.0) -> 0 | G29: =IFERROR(__xludf.DUMMYFUNCTION("""COMPUTED_VALUE"""),0.0) -> 0 | H29: =IFERROR(__xludf.DUMMYFUNCTION("""COMPUTED_VALUE"""),"Damage") -> Damage
A30: =IFERROR(__xludf.DUMMYFUNCTION("""COMPUTED_VALUE"""),2021.0) -> 2021 | B30: =IFERROR(__xludf.DUMMYFUNCTION("""COMPUTED_VALUE"""),10.0) -> 10 | C30: =IFERROR(__xludf.DUMMYFUNCTION("""COMPUTED_VALUE"""),1.0) -> 1 | D30: =IFERROR(__xludf.DUMMYFUNCTION("""COMPUTED_VALUE"""),1004011.0) -> 1004011 | E30: =IFERROR(__xludf.DUMMYFUNCTION("""COMPUTED_VALUE"""),1.0) -> 1 | F30: =IFERROR(__xludf.DUMMYFUNCTION("""COMPUTED_VALUE"""),0.0) -> 0 | G30: =IFERROR(__xludf.DUMMYFUNCTION("""COMPUTED_VALUE"""),5.0) -> 5 | H30: =IFERROR(__xludf.DUMMYFUNCTION("""COMPUTED_VALUE"""),"Return") -> Return
A31: =IFERROR(__xludf.DUMMYFUNCTION("""COMPUTED_VALUE"""),2021.0) -> 2021 | B31: =IFERROR(__xludf.DUMMYFUNCTION("""COMPUTED_VALUE"""),10.0) -> 10 | C31: =IFERROR(__xludf.DUMMYFUNCTION("""COMPUTED_VALUE"""),1.0) -> 1 | D31: =IFERROR(__xludf.DUMMYFUNCTION("""COMPUTED_VALUE"""),1003598.0) -> 1003598 | E31: =IFERROR(__xludf.DUMMYFUNCTION("""COMPUTED_VALUE"""),1.0) -> 1 | F31: =IFERROR(__xludf.DUMMYFUNCTION("""COMPUTED_VALUE"""),0.0) -> 0 | G31: =IFERROR(__xludf.DUMMYFUNCTION("""COMPUTED_VALUE"""),10.0) -> 10 | H31: =IFERROR(__xludf.DUMMYFUNCTION("""COMPUTED_VALUE"""),"Return") -> Return
A32: =IFERROR(__xludf.DUMMYFUNCTION("""COMPUTED_VALUE"""),2021.0) -> 2021 | B32: =IFERROR(__xludf.DUMMYFUNCTION("""COMPUTED_VALUE"""),10.0) -> 10 | C32: =IFERROR(__xludf.DUMMYFUNCTION("""COMPUTED_VALUE"""),1.0) -> 1 | D32: =IFERROR(__xludf.DUMMYFUNCTION("""COMPUTED_VALUE"""),1003593.0) -> 1003593 | E32: =IFERROR(__xludf.DUMMYFUNCTION("""COMPUTED_VALUE"""),2.0) -> 2 | F32: =IFERROR(__xludf.DUMMYFUNCTION("""COMPUTED_VALUE"""),0.0) -> 0 | G32: =IFERROR(__xludf.DUMMYFUNCTION("""COMPUTED_VALUE"""),0.0) -> 0 | H32: =IFERROR(__xludf.DUMMYFUNCTION("""COMPUTED_VALUE"""),"Return") -> Return
A33: =IFERROR(__xludf.DUMMYFUNCTION("""COMPUTED_VALUE"""),2021.0) -> 2021 | B33: =IFERROR(__xludf.DUMMYFUNCTION("""COMPUTED_VALUE"""),10.0) -> 10 | C33: =IFERROR(__xludf.DUMMYFUNCTION("""COMPUTED_VALUE"""),1.0) -> 1 | D33: =IFERROR(__xludf.DUMMYFUNCTION("""COMPUTED_VALUE"""),1003406.0) -> 1003406 | E33: =IFERROR(__xludf.DUMMYFUNCTION("""COMPUTED_VALUE"""),1.0) -> 1 | F33: =IFERROR(__xludf.DUMMYFUNCTION("""COMPUTED_VALUE"""),0.0) -> 0 | G33: =IFERROR(__xludf.DUMMYFUNCTION("""COMPUTED_VALUE"""),0.0) -> 0 | H33: =IFERROR(__xludf.DUMMYFUNCTION("""COMPUTED_VALUE"""),"Wrong product") -> Wrong product
A34: =IFERROR(__xludf.DUMMYFUNCTION("""COMPUTED_VALUE"""),2021.0) -> 2021 | B34: =IFERROR(__xludf.DUMMYFUNCTION("""COMPUTED_VALUE"""),10.0) -> 10 | C34: =IFERROR(__xludf.DUMMYFUNCTION("""COMPUTED_VALUE"""),1.0) -> 1 | D34: =IFERROR(__xludf.DUMMYFUNCTION("""COMPUTED_VALUE"""),1003629.0) -> 1003629 | E34: =IFERROR(__xludf.DUMMYFUNCTION("""COMPUTED_VALUE"""),5.0) -> 5 | F34: =IFERROR(__xludf.DUMMYFUNCTION("""COMPUTED_VALUE"""),0.0) -> 0 | G34: =IFERROR(__xludf.DUMMYFUNCTION("""COMPUTED_VALUE"""),8.09) -> 8.09 | H34: =IFERROR(__xludf.DUMMYFUNCTION("""COMPUTED_VALUE"""),"Return") -> Return
A35: =IFERROR(__xludf.DUMMYFUNCTION("""COMPUTED_VALUE"""),2021.0) -> 2021 | B35: =IFERROR(__xludf.DUMMYFUNCTION("""COMPUTED_VALUE"""),10.0) -> 10 | C35: =IFERROR(__xludf.DUMMYFUNCTION("""COMPUTED_VALUE"""),1.0) -> 1 | D35: =IFERROR(__xludf.DUMMYFUNCTION("""COMPUTED_VALUE"""),1003326.0) -> 1003326 | E35: =IFERROR(__xludf.DUMMYFUNCTION("""COMPUTED_VALUE"""),5.0) -> 5 | F35: =IFERROR(__xludf.DUMMYFUNCTION("""COMPUTED_VALUE"""),0.0) -> 0 | G35: =IFERROR(__xludf.DUMMYFUNCTION("""COMPUTED_VALUE"""),0.0) -> 0 | H35: =IFERROR(__xludf.DUMMYFUNCTION("""COMPUTED_VALUE"""),"Damage") -> Damage
A36: =IFERROR(__xludf.DUMMYFUNCTION("""COMPUTED_VALUE"""),2021.0) -> 2021 | B36: =IFERROR(__xludf.DUMMYFUNCTION("""COMPUTED_VALUE"""),10.0) -> 10 | C36: =IFERROR(__xludf.DUMMYFUNCTION("""COMPUTED_VALUE"""),1.0) -> 1 | D36: =IFERROR(__xludf.DUMMYFUNCTION("""COMPUTED_VALUE"""),1003967.0) -> 1003967 | E36: =IFERROR(__xludf.DUMMYFUNCTION("""COMPUTED_VALUE"""),6.0) -> 6 | F36: =IFERROR(__xludf.DUMMYFUNCTION("""COMPUTED_VALUE"""),0.0) -> 0 | G36: =IFERROR(__xludf.DUMMYFUNCTION("""COMPUTED_VALUE"""),0.0) -> 0 | H36: =IFERROR(__xludf.DUMMYFUNCTION("""COMPUTED_VALUE"""),"Return") -> Return
A37: =IFERROR(__xludf.DUMMYFUNCTION("""COMPUTED_VALUE"""),2021.0) -> 2021 | B37: =IFERROR(__xludf.DUMMYFUNCTION("""COMPUTED_VALUE"""),10.0) -> 10 | C37: =IFERROR(__xludf.DUMMYFUNCTION("""COMPUTED_VALUE"""),1.0) -> 1 | D37: =IFERROR(__xludf.DUMMYFUNCTION("""COMPUTED_VALUE"""),1003650.0) -> 1003650 | E37: =IFERROR(__xludf.DUMMYFUNCTION("""COMPUTED_VALUE"""),1.0) -> 1 | F37: =IFERROR(__xludf.DUMMYFUNCTION("""COMPUTED_VALUE"""),0.0) -> 0 | G37: =IFERROR(__xludf.DUMMYFUNCTION("""COMPUTED_VALUE"""),0.0) -> 0 | H37: =IFERROR(__xludf.DUMMYFUNCTION("""COMPUTED_VALUE"""),"Damage") -> Damage
A38: =IFERROR(__xludf.DUMMYFUNCTION("""COMPUTED_VALUE"""),2021.0) -> 2021 | B38: =IFERROR(__xludf.DUMMYFUNCTION("""COMPUTED_VALUE"""),10.0) -> 10 | C38: =IFERROR(__xludf.DUMMYFUNCTION("""COMPUTED_VALUE"""),1.0) -> 1 | D38: =IFERROR(__xludf.DUMMYFUNCTION("""COMPUTED_VALUE"""),1003389.0) -> 1003389 | E38: =IFERROR(__xludf.DUMMYFUNCTION("""COMPUTED_VALUE"""),4.0) -> 4 | F38: =IFERROR(__xludf.DUMMYFUNCTION("""COMPUTED_VALUE"""),0.0) -> 0 | G38: =IFERROR(__xludf.DUMMYFUNCTION("""COMPUTED_VALUE"""),0.0) -> 0 | H38: =IFERROR(__xludf.DUMMYFUNCTION("""COMPUTED_VALUE"""),"Wrong product") -> Wrong product
A39: =IFERROR(__xludf.DUMMYFUNCTION("""COMPUTED_VALUE"""),2021.0) -> 2021 | B39: =IFERROR(__xludf.DUMMYFUNCTION("""COMPUTED_VALUE"""),10.0) -> 10 | C39: =IFERROR(__xludf.DUMMYFUNCTION("""COMPUTED_VALUE"""),1.0) -> 1 | D39: =IFERROR(__xludf.DUMMYFUNCTION("""COMPUTED_VALUE"""),1003330.0) -> 1003330 | E39: =IFERROR(__xludf.DUMMYFUNCTION("""COMPUTED_VALUE"""),3.0) -> 3 | F39: =IFERROR(__xludf.DUMMYFUNCTION("""COMPUTED_VALUE"""),0.0) -> 0 | G39: =IFERROR(__xludf.DUMMYFUNCTION("""COMPUTED_VALUE"""),0.0) -> 0 | H39: =IFERROR(__xludf.DUMMYFUNCTION("""COMPUTED_VALUE"""),"Return") -> Return
A40: =IFERROR(__xludf.DUMMYFUNCTION("""COMPUTED_VALUE"""),2021.0) -> 2021 | B40: =IFERROR(__xludf.DUMMYFUNCTION("""COMPUTED_VALUE"""),10.0) -> 10 | C40: =IFERROR(__xludf.DUMMYFUNCTION("""COMPUTED_VALUE"""),1.0) -> 1 | D40: =IFERROR(__xludf.DUMMYFUNCTION("""COMPUTED_VALUE"""),1003780.0) -> 1003780 | E40: =IFERROR(__xludf.DUMMYFUNCTION("""COMPUTED_VALUE"""),2.0) -> 2 | F40: =IFERROR(__xludf.DUMMYFUNCTION("""COMPUTED_VALUE"""),0.0) -> 0 | G40: =IFERROR(__xludf.DUMMYFUNCTION("""COMPUTED_VALUE"""),0.0) -> 0 | H40: =IFERROR(__xludf.DUMMYFUNCTION("""COMPUTED_VALUE"""),"Return") -> Return
...

Sheet Exploration>>

Sheet Explo_refund_reason
A1: year | B1: month | C1: day | D1: orders_id | E1: ref_turnover | F1: ref_ship | G1: ref_coupon | H1: ref_reason | I1: turnover_per_order
A2: 2021 | B2: 10 | C2: 1 | D2: 1003644 | E2: 6 | F2: 0 | G2: 0 | H2: Damage | I2: =sumıf(Sales!B:B,D2,Sales!G:G) -> 53.54
A3: 2021 | B3: 10 | C3: 1 | D3: 1003989 | E3: 3 | F3: 0 | G3: 0 | H3: Wrong product | I3: =sumıf(Sales!B:B,D3,Sales!G:G) -> 247.63
A4: 2021 | B4: 10 | C4: 1 | D4: 1003585 | E4: 1 | F4: 0 | G4: 0 | H4: Wrong product | I4: =sumıf(Sales!B:B,D4,Sales!G:G) -> 41.48
A5: 2021 | B5: 10 | C5: 1 | D5: 1003362 | E5: 3 | F5: 0 | G5: 0 | H5: Wrong product | I5: =sumıf(Sales!B:B,D5,Sales!G:G) -> 183.53
A6: 2021 | B6: 10 | C6: 1 | D6: 1003322 | E6: 1 | F6: 0 | G6: 10 | H6: Return | I6: =sumıf(Sales!B:B,D6,Sales!G:G) -> 200.76
A7: 2021 | B7: 10 | C7: 1 | D7: 1003992 | E7: 13 | F7: 0 | G7: 0 | H7: Return | I7: =sumıf(Sales!B:B,D7,Sales!G:G) -> 16.41
A8: 2021 | B8: 10 | C8: 1 | D8: 1003540 | E8: 2 | F8: 0 | G8: 0 | H8: Return | I8: =sumıf(Sales!B:B,D8,Sales!G:G) -> 55.63
A9: 2021 | B9: 10 | C9: 1 | D9: 1003712 | E9: 0.75957991 | F9: 0 | G9: 10 | H9: Return | I9: =sumıf(Sales!B:B,D9,Sales!G:G) -> 111.66
A10: 2021 | B10: 10 | C10: 1 | D10: 1003802 | E10: 2 | F10: 0 | G10: 0 | H10: Damage | I10: =sumıf(Sales!B:B,D10,Sales!G:G) -> 140.18
A11: 2021 | B11: 10 | C11: 1 | D11: 1003568 | E11: 3 | F11: 5.75 | G11: 0 | H11: Return | I11: =sumıf(Sales!B:B,D11,Sales!G:G) -> 107.54
A12: 2021 | B12: 10 | C12: 1 | D12: 1003822 | E12: 2 | F12: 0 | G12: 0 | H12: Return | I12: =sumıf(Sales!B:B,D12,Sales!G:G) -> 58.64
A13: 2021 | B13: 10 | C13: 1 | D13: 1003395 | E13: 1 | F13: 0 | G13: 10 | H13: Return | I13: =sumıf(Sales!B:B,D13,Sales!G:G) -> 111.61
... A687: 2021 | B687: 10 | C687: 15 | D687: 1004022 | E687: 13 | F687: 0 | G687: 0 | H687: Damage | I687: =sumıf(Sales!B:B,D687,Sales!G:G) -> 98.24

Sheet Deliverables>>

Sheet Global_quality_vision

Sheet RESULTS
A1: 🧪 PRODUCTION TEAM
A3: Mission of the team
A4: Ürün kalitesinden kaynaklanabilecek olası kayıpları belirlemek.
A7: Main KPIs
A9: KPI name | B9: Definition | D9: Why is it useful for the team?
A10: % reason of return(İade Nedeni Yüzdesi) | B10: Belirli bir nedenden kaynaklanan iadelerin yüzdesi | D10: Ekibin çabasını tek bir sorunun çözümüne odaklamasını sağlar
A11: % of return per product(Ürün Başına İade Yüzdesi) | B11: Ürün A için iade sayısı / Ürün A sipariş sayısı | D11: Ürünü iptal etme veya yeniden tasarlama kararı almak
A19: Main results of your analysis
A21: İadeler çoğunlukla fikir değişikliğinden kaynaklanıyor
A22: İade edilen siparişler arasında en yaygın neden gönüllü iade (%51), bunu hasar (%25) ve yanlış ürün (%23) takip ediyor.
A24: Hasardan kaynaklanan iadelerin finansal etkisi daha düşük
A25: Hasar, iadelerin %25’ini oluştursa da, geri kazanılan net ciro orijinal değerin %94’ü civarında kalıyor.
A27: İadeler, iade edilen siparişlerde %7 ciro kaybına yol açıyor
A28: Bu 686 iade üzerinden sadece %93’ü korunuyor (kupon ve kargo dahil).

Sheet Refund_finance
B7: =SUM(B5+C5+D5) -> 4671.6563
A8: Weight of Refund | B8: =B5/B7 -> 0.65840595 | C8: =C5/B7 -> 0.095188937 | D8: =D5/B7 -> 0.24640511
